Workbook

Sheet Assumptions
A1: PleoChrome — Deal Assumptions
A2: Yellow cells are editable inputs. Blue cells are calculated. All costs in USD.
A4: Parameter | B4: Value | C4: Unit | D4: Source / Justification
A5: ASSET DETAILS
A6: Stone Type | B6: Burmese Ruby | D6: Pigeon's blood, Mogok origin
A7: Carat Weight | B7: 55 | C7: ct | D7: Comparable: Estrela de Fura (55.22ct, $34.8M)
A8: Treatment | B8: No Heat | D8: Unheated commands 2-5x premium
A9: Claimed Asset Value | B9: 55000000 | C9: $ | D9: Enter the stone owner's claimed value
A10: Appraisal Discount (%) | B10: 0.127 | C10: % | D10: 3-Appraisal Rule: avg of 2 lowest typically 10-15% below claimed
A11: Offering Value | B11: =B9*(1-B10) | C11: $ | D11: Claimed Value x (1 - Appraisal Discount)
A12: Token Price (Min Investment) | B12: 100000 | C12: $ | D12: Reg D 506(c) accredited; $200K+ allows self-certification
A13: Total Tokens | B13: =INT(B11/B12) | C13: # | D13: Offering Value / Token Price
A15: PLEOCHROME FEE STRUCTURE
A16: Setup Fee Rate | B16: 0.02 | C16: % | D16: Industry standard 1-3%. Collected at engagement.
A17: Success Fee Rate | B17: 0.015 | C17: % | D17: 0.5-3%. Collected at token sale close. $0 if offering fails.
A18: Annual Admin Fee Rate | B18: 0.0075 | C18: % | D18: 0.5-1.0%. Recurring revenue starting Year 2.
A19: BD Placement Rate | B19: 0.07 | C19: % | D19: 5-7% for broker-dealer distribution. 0% if direct placement.
A20: Setup Fee ($) | B20: =B9*B16 | C20: $ | D20: Asset Value x Setup Fee Rate
A21: Success Fee ($) | B21: =B11*B17 | C21: $ | D21: Offering Value x Success Fee Rate
A22: Annual Admin Fee ($) | B22: =B11*B18 | C22: $ | D22: Offering Value x Admin Fee Rate
A23: BD Placement Fee ($) | B23: =B11*B19 | C23: $ | D23: Offering Value x BD Rate

Sheet Deal Model
A1: Stone-Level Deal Model — Phase-by-Phase Costs
A2: Yellow = editable override. Blue = auto-calculated from Assumptions tab.
B4: Offering Value | C4: PleoChrome Costs | D4: Asset Holder Costs | E4: BD Fee | F4: Net to Holder
A5: TOTALS | B5: =Assumptions!B11 | C5: =D45 | D5: =D46 | E5: =D47 | F5: =Assumptions!B11-D45-D46-D47-Assumptions!B20-Assumptions!B21
A7: Line Item | B7: Default ($) | C7: Override ($) | D7: Actual ($) | E7: Paid By | F7: Source / When Due
A8: PHASE 1: ACQUISITION (Days 1-14)
A9: KYC / KYB on Asset Holder | B9: 50 | D9: =IF(C9<>"",C9,B9) | E9: PleoChrome | F9: Veriff/Sumsub $0.80/check. Brickken includes 150. | Day 1-3
A10: Sanctions & PEP Screening | B10: 100 | D10: =IF(C10<>"",C10,B10) | E10: PleoChrome | F10: OFAC/EU/UN screening. Bundled with KYC or $10-50/ea. | Day 1-3
A11: Provenance Research | B11: 2500 | D11: =IF(C11<>"",C11,B11) | E11: Asset Holder | F11: Legal title search. 10-20hrs at $150-$250/hr. | Day 3-10
A12: Intake Agreement (Legal) | B12: 2500 | D12: =IF(C12<>"",C12,B12) | E12: PleoChrome | F12: Boutique attorney. Template after first deal. | Day 5-14
A13: PHASE 2: PREPARATION (Days 14-84)
A14: GIA Grading Report | B14: 0 | D14: =IF(C14<>"",C14,B14) | E14: Asset Holder | F14: Most $50M+ stones already certified. $300-500 if needed. | Day 14-35
A15: SSEF Origin Report | B15: 0 | D15: =IF(C15<>"",C15,B15) | E15: Asset Holder | F15: CHF 4,000 if needed. Likely already exists. | Day 14-35
A16: Gubelin Report (Optional) | B16: 0 | D16: =IF(C16<>"",C16,B16) | E16: Asset Holder | F16: CHF 4,000-5,000 if needed for triple-lab cert. | Day 14-35
A17: Independent Appraisal #1 | B17: 7500 | D17: =IF(C17<>"",C17,B17) | E17: Asset Holder | F17: CGA/MGA, USPAP compliant. $150-250/hr × 20-40hrs. | Day 28-38
A18: Independent Appraisal #2 | B18: 7500 | D18: =IF(C18<>"",C18,B18) | E18: Asset Holder | F18: Sequential. Independent of Appraiser #1. | Day 38-48
A19: Independent Appraisal #3 | B19: 7500 | D19: =IF(C19<>"",C19,B19) | E19: Asset Holder | F19: Completes 3-Appraisal Rule. | Day 48-56
A20: Transit Insurance | B20: 10000 | D20: =IF(C20<>"",C20,B20) | E20: Asset Holder | F20: 2-4 insured transits at $2K-5K each. | Days 28-65
A21: Vault Custody (Year 1) | B21: 55000 | D21: =IF(C21<>"",C21,B21) | E21: Asset Holder | F21: Brink's/Malca-Amit. 0.10% of value, negotiated. | Day 56+ ongoing
A22: Specie Insurance (Year 1) | B22: 55000 | D22: =IF(C22<>"",C22,B22) | E22: Asset Holder | F22: Lloyd's/AXA XL. 0.10% vault-stored rate. | Day 56+ ongoing
A23: Chainlink Oracle Integration | B23: 2500 | D23: =IF(C23<>"",C23,B23) | E23: PleoChrome | F23: BUILD program or minimal LINK gas fees. | Day 42-70
A24: Chainlink LINK Fees (Year 1) | B24: 1200 | D24: =IF(C24<>"",C24,B24) | E24: PleoChrome | F24: $100-200/mo for monthly PoR attestation. | Day 70+ ongoing
A25: SPV Formation (Series LLC) | B25: 750 | D25: =IF(C25<>"",C25,B25) | E25: PleoChrome | F25: Wyoming $100 + RA $25/yr + template OA $500. | Day 30-45
... A29: Photo & Media | B29: 2000 | D29: =IF(C29<>"",C29,B29) | E29: Asset Holder | F29: 8+ angles, macro, 360 video. $1K-3K. | Day 56-65
A30: PHASE 3: TOKENIZATION (Days 63-84)
A31: Brickken Platform (Year 1) | B31: 5500 | D31: =IF(C31<>"",C31,B31) | E31: PleoChrome | F31: Advanced tier EUR 5,000/yr. Includes 150 KYCs. | Day 63
A32: Configuration Review | B32: 3500 | D32: =IF(C32<>"",C32,B32) | E32: PleoChrome | F32: Not full audit — Brickken contracts pre-audited. | Day 63-75
A33: Development & Testing | B33: 5000 | D33: =IF(C33<>"",C33,B33) | E33: PleoChrome | F33: 10-30hrs config + testnet deploy. $200-400/hr. | Day 65-80
A34: Blockchain Gas Fees | B34: 100 | D34: =IF(C34<>"",C34,B34) | E34: PleoChrome | F34: Polygon: $0.01/tx. Multiple deploys = $50-200. | Day 80
A35: Blue Sky Filings (5 States) | B35: 1500 | D35: =IF(C35<>"",C35,B35) | E35: PleoChrome | F35: 3-5 target states. $100-500 each + filing service. | Day 80-84
A36: PHASE 4: DISTRIBUTION (Days 84-120)
A37: Marketing & Investor Acq. | B37: 3000 | D37: =IF(C37<>"",C37,B37) | E37: PleoChrome | F37: LinkedIn Sales Nav + ads + direct outreach. | Day 84-120
A38: Investor KYC & Accreditation | B38: 0 | D38: =IF(C38<>"",C38,B38) | E38: PleoChrome | F38: Covered by Brickken 150 KYCs. Self-cert for $200K+. | Day 90-120
A39: Transfer Agent | B39: 0 | D39: =IF(C39<>"",C39,B39) | E39: PleoChrome | F39: ERC-3643 on-chain registry = TA per SEC Jan 2026. | N/A
A40: Investor Portal / Data Room | B40: 0 | D40: =IF(C40<>"",C40,B40) | E40: PleoChrome | F40: Built on existing Vercel site or Google Drive. | Day 80
A41: Compliance Monitoring (Year 1) | B41: 500 | D41: =IF(C41<>"",C41,B41) | E41: PleoChrome | F41: Built into Brickken + ERC-3643. Quarterly re-screen. | Day 120+ ongoing
A42: Annual AML Audit | B42: 3500 | D42: =IF(C42<>"",C42,B42) | E42: PleoChrome | F42: Boutique compliance consultant. $3K-5K. | Month 12
A44: COST SUMMARY
A45: PleoChrome Direct Costs | D45: =D9+D10+D12+D23+D24+D25+D26+D27+D28+D31+D32+D33+D34+D35+D37+D38+D39+D40+D41+D42
A46: Asset Holder Pass-Through Costs | D46: =D11+D14+D15+D16+D17+D18+D19+D20+D21+D22+D29
...

Sheet PleoChrome P&L
A1: PleoChrome P&L — Per-Deal + 5-Year Projection
A3: Revenue Stream | B3: Year 1 | C3: Year 2 | D3: Year 3 | E3: Year 4 | F3: Year 5 | G3: 5-Year Total
A4: Setup Fee | B4: =Assumptions!B20 | C4: 0 | D4: 0 | E4: 0 | F4: 0 | G4: =SUM(B4:F4)
A5: Success Fee | B5: =Assumptions!B21 | C5: 0 | D5: 0 | E5: 0 | F5: 0 | G5: =SUM(B5:F5)
A6: Secondary Transfer Fees (est.) | B6: 12000 | C6: 24000 | D6: 24000 | E6: 24000 | F6: 24000 | G6: =SUM(B6:F6)
A7: Annual Admin Fee | B7: 0 | C7: =Assumptions!B22 | D7: =Assumptions!B22 | E7: =Assumptions!B22 | F7: =Assumptions!B22 | G7: =SUM(B7:F7)
A8: Valuation Refresh Fee | B8: 0 | C8: 25000 | D8: 25000 | E8: 25000 | F8: 25000 | G8: =SUM(B8:F8)
A9: TOTAL REVENUE | B9: =SUM(B4:B8) | C9: =SUM(C4:C8) | D9: =SUM(D4:D8) | E9: =SUM(E4:E8) | F9: =SUM(F4:F8) | G9: =SUM(G4:G8)
A11: COSTS
A12: PleoChrome Direct Costs | B12: ='Deal Model'!D45 | C12: 0 | D12: 0 | E12: 0 | F12: 0 | G12: =SUM(B12:F12)
A13: Annual Ongoing (PleoChrome share) | B13: 0 | C13: 15000 | D13: 15000 | E13: 15000 | F13: 15000 | G13: =SUM(B13:F13)
A14: TOTAL COSTS | B14: =SUM(B12:B13) | C14: =SUM(C12:C13) | D14: =SUM(D12:D13) | E14: =SUM(E12:E13) | F14: =SUM(F12:F13) | G14: =SUM(G12:G13)
A15: NET INCOME | B15: =B9-B14 | C15: =C9-C14 | D15: =D9-D14 | E15: =E9-E14 | F15: =F9-F14 | G15: =G9-G14
A16: NET MARGIN | B16: =IF(B9=0,0,B15/B9) | C16: =IF(C9=0,0,C15/C9) | D16: =IF(D9=0,0,D15/D9) | E16: =IF(E9=0,0,E15/E9) | F16: =IF(F9=0,0,F15/F9) | G16: =IF(G9=0,0,G15/G9)
A19: ASSET HOLDER ECONOMICS
A20: Claimed Asset Value | B20: =Assumptions!B9
A21: Offering Value (after appraisal discount) | B21: =Assumptions!B11
A22: Less: BD Placement Fee | B22: =-Assumptions!B23
A23: Less: PleoChrome Setup Fee | B23: =-Assumptions!B20
A24: Less: PleoChrome Success Fee | B24: =-Assumptions!B21
A25: Less: Asset Holder Pass-Through Costs | B25: =-'Deal Model'!D46
A26: NET PROCEEDS TO ASSET HOLDER | B26: =SUM(B21:B25)
A27: % of Claimed Value | B27: =B26/B20

Sheet Pricing Sources
A1: Pricing Sources of Truth — All Assumptions Sourced
A3: Cost Category | B3: Rate / Amount | C3: Basis | D3: Last Verified | E3: Source URL / Reference
A4: GIA Colored Stone Report (50+ ct) | B4: $300-$500 | C4: Per report | D4: Mar 2026 | E4: gia.edu/gem-lab-fee-schedule
A5: SSEF Origin Report (50-100 ct) | B5: CHF 4,000 | C5: Per report | D5: Mar 2026 | E5: ssef.ch/testing-prices
A6: Gubelin ID + Origin | B6: ~CHF 4,000 | C6: Per report | D6: Mar 2026 | E6: gubelingemlab.com
A7: USPAP Appraisal (CGA/MGA) | B7: $150-$250/hr | C7: Hourly (not % of value) | D7: Mar 2026 | E7: americangemsociety.org/CGA
A8: Vault Custody (Brink's negotiated) | B8: 0.10-0.15% | C8: Annual, of asset value | D8: Mar 2026 | E8: us.brinks.com/precious-metals
A9: Vault Custody (Malca-Amit FTZ) | B9: 0.10-0.25% | C9: Annual, of asset value | D9: Mar 2026 | E9: malca-amit.com/vaults-ftz
A10: Specie Insurance (vault-stored) | B10: 0.10-0.15% | C10: Annual, of insured value | D10: Mar 2026 | E10: AXA XL / Lloyd's syndicate
A11: Transit Insurance (inland marine) | B11: 0.25-1.0% | C11: Per transit event | D11: Mar 2026 | E11: Marsh Fine Art & Specie
A12: Brickken Advanced Tier | B12: EUR 5,000/yr | C12: Annual subscription | D12: Mar 2026 | E12: brickken.com/plans
A13: Brickken Enterprise Tier | B13: EUR 22,000/yr | C13: Annual subscription | D13: Mar 2026 | E13: brickken.com/plans
A14: Chainlink BUILD Program | B14: $0 cash | C14: Token supply commitment (3-7%) | D14: Mar 2026 | E14: chain.link/build-program
... A31: AML Audit (mid-tier firm) | B31: $10K-$25K | C31: Annual | D31: Mar 2026 | E31: Industry benchmark

Sheet Payment Timeline
A1: 120-Day Payment Timeline — When Every Cost Hits
A3: Event | B3: Day Start | C3: Day End | D3: Cost Out | E3: Revenue In | F3: Running PC Balance | G3: Phase
A4: Engagement signed → Setup fee collected | B4: 1 | C4: 1 | D4: 0 | E4: =Assumptions!B20 | F4: =E4-D4 | G4: Acquisition
A5: KYC/KYB + Sanctions screening | B5: 1 | C5: 3 | D5: 150 | E5: 0 | F5: =F4+E5-D5 | G5: Acquisition
A6: Provenance research (asset holder cost) | B6: 3 | C6: 10 | D6: 0 | E6: 0 | F6: =F5+E6-D6 | G6: Acquisition
A7: Intake agreement (legal) | B7: 5 | C7: 14 | D7: 2500 | E7: 0 | F7: =F6+E7-D7 | G7: Acquisition
A8: Stone shipped to GIA/SSEF | B8: 14 | C8: 14 | D8: 0 | E8: 0 | F8: =F7+E8-D8 | G8: Preparation
A9: Lab reports received + verified | B9: 28 | C9: 35 | D9: 0 | E9: 0 | F9: =F8+E9-D9 | G9: Preparation
A10: Appraiser 1 inspection + report | B10: 28 | C10: 38 | D10: 0 | E10: 0 | F10: =F9+E10-D10 | G10: Preparation
A11: Appraiser 2 inspection + report | B11: 38 | C11: 48 | D11: 0 | E11: 0 | F11: =F10+E11-D11 | G11: Preparation
A12: Appraiser 3 inspection + report | B12: 48 | C12: 56 | D12: 0 | E12: 0 | F12: =F11+E12-D12 | G12: Preparation
A13: SPV formation filed | B13: 30 | C13: 45 | D13: 750 | E13: 0 | F13: =F12+E13-D13 | G13: Preparation
A14: PPM drafting begins | B14: 35 | C14: 70 | D14: 10000 | E14: 0 | F14: =F13+E14-D14 | G14: Preparation
A15: Subscription + Token agreements | B15: 50 | C15: 70 | D15: 4500 | E15: 0 | F15: =F14+E15-D15 | G15: Preparation
A16: Chainlink PoR integration | B16: 42 | C16: 70 | D16: 2500 | E16: 0 | F16: =F15+E16-D16 | G16: Preparation
... A24: First investor KYC + subscription | B24: 90 | C24: 90 | D24: 0 | E24: 0 | F24: =F23+E24-D24 | G24: Distribution
A25: Token sale closes → Success fee | B25: 120 | C25: 120 | D25: 0 | E25: =Assumptions!B21 | F25: =F24+E25-D25 | G25: Distribution
A26: Compliance monitoring begins | B26: 120 | C26: 120 | D26: 500 | E26: 0 | F26: =F25+E26-D26 | G26: Distribution
